<?xml version="1.0"?>
<robot name="wall_e" xmlns:xacro="http://www.ros.org/wiki/xacro">

  <!-- ── PROPERTIES ── -->
  <xacro:property name="base_length"   value="0.365"/>  <!-- 8.5 inches -->
  <xacro:property name="base_width"    value="0.390"/>   <!-- 46cm total -->
  <xacro:property name="base_height"   value="0.245"/>   <!-- 56cm -->
  <xacro:property name="track_width"   value="0.32"/>   <!-- 32cm center to center -->
  <xacro:property name="track_thick"   value="0.07"/>   <!-- 7cm track thickness -->
  <xacro:property name="wheel_radius"  value="0.05"/>   <!-- 5cm -->
  <xacro:property name="cam_height"    value="0.245"/>   <!-- 20cm off ground -->
  <xacro:property name="cam_forward"   value="0.15"/>  <!-- 14.7cm forward of center -->
  <!-- <xacro:property name="pi"            value="3.141592653  58979"/> -->

  <!-- ── BASE FOOTPRINT ── -->
  <link name="base_footprint"/>

  <joint name="base_footprint_joint" type="fixed">
    <parent link="base_footprint"/>
    <child  link="base_link"/>
    <origin xyz="0 0 ${wheel_radius}" rpy="0 0 0"/>
  </joint>

  <!-- ── BASE LINK ── -->
  <link name="base_link">
    <visual>
      <geometry>
        <box size="${base_length} ${base_width} ${base_height}"/>
      </geometry>
      <material name="grey">
        <color rgba="0.5 0.5 0.5 1.0"/>
      </material>
    </visual>
    <collision>
      <geometry>
        <box size="${base_length} ${base_width} ${base_height}"/>
      </geometry>
    </collision>
    <inertial>
      <mass value="4.0"/>
      <inertia ixx="0.05" ixy="0" ixz="0"
               iyy="0.05" iyz="0"
               izz="0.08"/>
    </inertial>
  </link>

  <!-- ── LEFT TRACK ── -->
  <link name="left_track">
    <visual>
      <geometry>
        <box size="${base_length} ${track_thick} ${wheel_radius*2}"/>
      </geometry>
      <material name="black">
        <color rgba="0.1 0.1 0.1 1.0"/>
      </material>
    </visual>
    <collision>
      <geometry>
        <box size="${base_length} ${track_thick} ${wheel_radius*2}"/>
      </geometry>
    </collision>
    <inertial>
      <mass value="0.5"/>
      <inertia ixx="0.001" ixy="0" ixz="0"
               iyy="0.001" iyz="0"
               izz="0.001"/>
    </inertial>
  </link>

  <joint name="left_track_joint" type="continuous">
    <parent link="base_link"/>
    <child  link="left_track"/>
    <origin xyz="0 ${track_width/2} ${-base_height/2}" rpy="0 0 0"/>
    <axis xyz="0 1 0"/>
  </joint>

  <!-- ── RIGHT TRACK ── -->
  <link name="right_track">
    <visual>
      <geometry>
        <box size="${base_length} ${track_thick} ${wheel_radius*2}"/>
      </geometry>
      <material name="black">
        <color rgba="0.1 0.1 0.1 1.0"/>
      </material>
    </visual>
    <collision>
      <geometry>
        <box size="${base_length} ${track_thick} ${wheel_radius*2}"/>
      </geometry>
    </collision>
    <inertial>
      <mass value="0.5"/>
      <inertia ixx="0.001" ixy="0" ixz="0"
               iyy="0.001" iyz="0"
               izz="0.001"/>
    </inertial>
  </link>

  <joint name="right_track_joint" type="continuous">
    <parent link="base_link"/>
    <child  link="right_track"/>
    <origin xyz="0 ${-track_width/2} ${-base_height/2}" rpy="0 0 0"/>
    <axis xyz="0 1 0"/>
  </joint>

  <!-- ── D435 CAMERA ── -->
  <link name="camera_link">
    <visual>
      <geometry>
        <box size="0.09 0.025 0.025"/>
      </geometry>
      <material name="blue">
        <color rgba="0.0 0.0 0.8 1.0"/>
      </material>
    </visual>
    <collision>
      <geometry>
        <box size="0.09 0.025 0.025"/>
      </geometry>
    </collision>
    <inertial>
      <mass value="0.072"/>
      <inertia ixx="0.0001" ixy="0" ixz="0"
               iyy="0.0001" iyz="0"
               izz="0.0001"/>
    </inertial>
  </link>

  <joint name="camera_joint" type="fixed">
    <parent link="base_link"/>
    <child  link="camera_link"/>
    <origin xyz="${cam_forward} 0 ${cam_height - wheel_radius}" rpy="0 0 0"/>
  </joint>

  <!-- Camera optical frame — required by RealSense driver -->
  <link name="camera_depth_optical_frame"/>

  <joint name="camera_optical_joint" type="fixed">
    <parent link="camera_link"/>
    <child  link="camera_depth_optical_frame"/>
    <origin xyz="0 0 0" rpy="${-pi/2} 0 ${-pi/2}"/>
  </joint>

  <link name="camera_color_optical_frame"/>

  <joint name="camera_color_optical_joint" type="fixed">
    <parent link="camera_link"/>
    <child  link="camera_color_optical_frame"/>
    <origin xyz="0 0 0" rpy="${-pi/2} 0 ${-pi/2}"/>
  </joint>

  <!-- ── IMU ── -->
  <link name="imu_link"/>

  <joint name="imu_joint" type="fixed">
    <parent link="base_link"/>
    <child  link="imu_link"/>
    <origin xyz="0 0 0" rpy="0 0 0"/>
  </joint>

</robot>